Workbook

Sheet Model Data
A1: Model Data | B1: inches | D1: =_xlfn.XLOOKUP(B1,I3:I4,J3:J4,J3,0,1) -> 25.4
A2: Control Name | B2: Input Value | D2: Calculated Value (mm) | E2: Derived Value | I2: Unit | J2: Value | L2: LightType | M2: Value | O2: QtyCollar | P2: Value | R2: EncType | S2: Value | U2: Marvel | V2: Value | X2: ABDType | Y2: Value | AA2: Material GA | AB2: Value | AD2: Ansultype | AE2: Value | AG2: Marvel Probe On which Collar | AH2: Value | AJ2: AccessABDLocation | AK2: Value | AM2: ThermStat Y/N | AN2: Value
A3: Overall Size and option | I3: inches | J3: 25.4 | L3: without Light | M3: 0 | O3: 1 Collar | P3: 1 | R3: No Flange | S3: 0 | U3: No Marvel | V3: 0 | X3: No ABD MBD | Y3: 0 | AA3: 16 GA | AB3: 1.51 | AD3: Ansul On Left | AE3: 1 | AG3: Marvel Probe On Left Collar | AH3: 1 | AJ3: Left ABD Access Panel | AK3: 1 | AM3: There is ThermStat | AN3: 1
A4: HL | B4: 96 | D4: =B4*$D$1 -> 2438.4 | I4: mm | J4: 1 | L4: with Led Lights | M4: 5 | O4: 2 Collars | P4: 2 | R4: Top Flange Only | S4: 1 | U4: Marvel Box On Hood Top | V4: 1 | X4: ABD 8 with Collar | Y4: 1 | AA4: 18 GA | AB4: 1.22 | AD4: Ansul On Left, Detect Both | AE4: 2 | AG4: Marvel Probe On Middle Collar | AH4: 3 | AJ4: Right ABD Access Panel | AK4: 2 | AM4: No ThermStat | AN4: 0
A5: HW | B5: 90 | D5: =B5*$D$1 -> 2286 | L5: with HCL Lights | M5: 7 | O5: 3 Collars | P5: 3 | R5: Top and Bottom flanges | S5: 2 | X5: ABD 6 Only | Y5: 2 | AA5: 20 GA | AB5: 0.9 | AD5: Ansul On Right | AE5: 3 | AG5: Marvel Probe On Right Collar | AH5: 2
A6: HT | B6: =15 -> 15 | D6: =B6*$D$1 -> 381 | E6: Fixed | L6: with ILG Lights | M6: 1 | R6: Bottom Flange Only | S6: 3 | X6: ABD 6 with Access Panel | Y6: 3 | AD6: Ansul On Right, Detect Both | AE6: 4
A7: WidthFront | B7: 6 | D7: =B7*$D$1 -> 152.4 | R7: Marine Type | S7: 4 | X7: ABD 6 with Collar | Y7: 4 | AD7: No Ansul | AE7: 0
A8: WidthPods | B8: =D8/D1 -> 30.403937 | D8: =(30.5-2*D48/25.4)*25.4 -> 772.26 | E8: Fixed | X8: ABD 6 with Collar and Access | Y8: 5
A9: WidthMiddle | B9: =D9/$D$1 -> 17.192126 | D9: =D5-D7-D10-2*D8 -> 436.68 | X9: MBD6 Only | Y9: 6
A10: WidthBack | B10: =E10 -> 6 | D10: =B10*$D$1 -> 152.4 | E10: =B7 -> 6 | X10: MBD6 with Collar | Y10: 7
A11: Marvel | B11: No Marvel | D11: =_xlfn.XLOOKUP(B11,U3:U4,V3:V4,0,1) -> 0
A12: ThermStat | B12: There is ThermStat | D12: =_xlfn.XLOOKUP(B12,AM3:AM4,AN3:AN4,AN3,0,1) -> 1
A13: QtyCollar | B13: 2 Collars | D13: =_xlfn.XLOOKUP(B13,O3:O5,P3:P5,P3,0,1) -> 2
A14: CollarFlangePosition | B14: Top Flange Only | D14: =_xlfn.XLOOKUP(B14,R3:R7,S3:S7,S3,0,1) -> 1
A15: ABDType | B15: No ABD MBD | D15: =_xlfn.XLOOKUP(B15,X3:X10,Y3:Y10,Y3,0,1) -> 0
A16: Left ABD Access Side | B16: Right ABD Access Panel | D16: =_xlfn.XLOOKUP(B16,AJ3:AJ4,AK3:AK4,AK3,0,1) -> 2
A17: Middle ABD Access Side | B17: Left ABD Access Panel | D17: =_xlfn.XLOOKUP(B17,AJ3:AJ4,AK3:AK4,AK3,0,1) -> 1
A18: Right ABD Access Side | B18: Right ABD Access Panel | D18: =_xlfn.XLOOKUP(B18,AJ3:AJ4,AK3:AK4,AK3,0,1) -> 2
A19: Marvel Probe On which Collar | B19: Marvel Probe On Middle Collar | D19: =_xlfn.XLOOKUP(B19,AG3:AG5,AH3:AH5,AH3,0,1) -> 3
A20: CollarLG | B20: 10 | D20: =B20*$D$1 -> 254
A21: CollarWidth | B21: 8 | D21: =B21*$D$1 -> 203.2
A22: CollarHT | B22: 4 | D22: =B22*$D$1 -> 101.6
A23: Collar1ToLeft | B23: =E23 -> 24 | D23: =B23*$D$1 -> 609.6 | E23: =B4/D13/2 -> 24
A24: Collars Dist | B24: =E24 -> 48 | D24: =B24*$D$1 -> 1219.2 | E24: =B4/D13 -> 48
A25: LightType | B25: with HCL Lights | D25: =_xlfn.XLOOKUP(B25,L3:L6,M3:M6,M3,0,1) -> 7
A26: LightQty | B26: =E26 -> 3 | D26: =B26 -> 3 | E26: =IF(B4>=156,5,IF(B4>=120,4, IF(B4>=84,3,IF(B4>=48,2,1 )))) -> 3
A27: LightToFront | B27: =E27 -> 45 | D27: =B27*$D$1 -> 1143 | E27: =B8+B7+B9/2 -> 45
A28: LigthToLeft | B28: =E28 -> 16 | D28: =B28*$D$1 -> 406.4 | E28: =B4/B26/2 -> 16
A29: Lights Dist | B29: =E29 -> 32 | D29: =B29*$D$1 -> 812.8 | E29: =B4/B26 -> 32
A30: Ansultype | B30: Ansul On Left | D30: =_xlfn.XLOOKUP(B30,AD3:AD7,AE3:AE7,AE3,0,1) -> 1
A31: AnsulDropQty | B31: 1 | D31: =B31 -> 1
A32: AnsulToFront | B32: 38 | D32: =B32*$D$1 -> 965.2 | F32: =B7+B8 -> 36.403937 | G32: =B27 -> 45
A33: A1 | B33: 6 | D33: =B33*$D$1 -> 152.4
A34: A2 | B34: 6 | D34: =B34*$D$1 -> 152.4
A35: A3 | B35: 6 | D35: =B35*$D$1 -> 152.4
A36: A4 | B36: 6 | D36: =B36*$D$1 -> 152.4
A37: A5 | B37: 6 | D37: =B37*$D$1 -> 152.4
A38: A6 | B38: 6 | D38: =B38*$D$1 -> 152.4
A39: A7 | B39: 6 | D39: =B39*$D$1 -> 152.4
A40: A8 | B40: 6 | D40: =B40*$D$1 -> 152.4
...

Sheet ToSolidworks
A1: ToSolidworks
A2: Command | B2: SolidWorks Object | C2: Value | D2: Status | E2: ConfigurationName | G2: Comment
A3: Start | B3: MainAssembly | C3: TRUE | D3: OK
A4: AttributeCustom | B4: Note1 | C4: ="VC2V Hood Size: "&'Model Data'!B4&"X"&'Model Data'!B5&"X"&'Model Data'!B6&"X"&'Model Data'!B7 -> VC2V Hood Size: 96X90X15X6 | D4: OK
A5: AttributeCustom | B5: Note2 | C5: ='Model Data'!B13&IF('Model Data'!D15=0,""," with "&'Model Data'!B15)&" : L"&'Model Data'!B20&" W"&'Model Data'!B21&" H"&'Model Data'!B22&IF('Model Data'!D25=0,"",CHAR(10)&'Model Data'!B25&" Qty="&'Model Data'!B26) -> 2 Collars : L10 W8 H4 with HCL Lights Qty=3 | D5: OK
A6: AttributeCustom | B6: Note3 | C6: ='Model Data'!B11&", "&'Model Data'!B12&IF('Model Data'!D30=0,"",CHAR(10)&'Model Data'!B30&", Drops Qty="&'Model Data'!B31) -> No Marvel, There is ThermStat Ansul On Left, Drops Qty=1 | D6: OK
A7: AttributeCustom | B7: notes | C7: =C4&CHAR(10)&"Crate Size: L"&'Model Data'!B4+4&" W"&'Model Data'!B5+12&" H"&'Model Data'!B6+12&CHAR(10)&C5&CHAR(10)&C6 -> VC2V Hood Size: 96X90X15X6 Crate Size: L100 W102 H27 2 Collars : L10 W8 H4 with HCL Lights Qty=3 No Marvel, There is ThermStat Ansul On Left, Drops Qty=1 | D7: OK
A8: AttributeConfig | B8: CodeModel | C8: =IF(LEN(G8)>10,"special",G8) -> special | D8: OK | E8: Default | G8: ='Model Data'!B4&'Model Data'!B5&'Model Data'!B7&'Model Data'!B10&'Model Data'!D13&'Model Data'!B20&'Model Data'!B21&'Model Data'!B22&'Model Data'!D25&'Model Data'!B26&'Model Data'!D11&'Model Data'!D12&'Model Data'!D30&'Model Data'!D31 -> 96906621084730111
A9: Stop | D9: OK
A10: Void | D10: -
A11: Start | B11: VC2V-Skeleton-1@VC2V00 | C11: TRUE | D11: OK
A12: Equation | B12: 0 | C12: ="""CollarQty""="&'Model Data'!D13& " 'Qty Collars" -> "CollarQty"=2 'Qty Collars | D12: OK
A13: Equation | B13: 1 | C13: ="""CollarFlangePosition""="&'Model Data'!D14& " '0 is no flanges, 1 top flange only, 2 topandbottom flangle, 3 bottom flange only,4 Marine Damper Flange" -> "CollarFlangePosition"=1 '0 is no flanges, 1 top flange only, 2 topandbottom flangle, 3 bottom flange only,4 Marine Damper Flange | D13: OK
A14: Equation | B14: 2 | C14: ="""LightType""="&'Model Data'!D25& " 'IncandescentLight 1; FL48 2; FL36 3;Ril 4;Led 5;HCL USA 7" -> "LightType"=7 'IncandescentLight 1; FL48 2; FL36 3;Ril 4;Led 5;HCL USA 7 | D14: OK
A15: Equation | B15: 3 | C15: ="""QLight""="&'Model Data'!D26& " 'Qty Lights" -> "QLight"=3 'Qty Lights | D15: OK
A16: Equation | B16: 4 | C16: ="""Marvel""="&'Model Data'!D11&" '0 no marvel, 1 Marvel Box top" -> "Marvel"=0 '0 no marvel, 1 Marvel Box top | D16: OK
A17: Equation | B17: 5 | C17: ="""MarvelCollarLocation""="&IF('Model Data'!D13=1,1,IF(AND('Model Data'!D13=2,'Model Data'!D19<>1),2,'Model Data'!D19))& " '0 is no, 1 is Left, 2 is right,3 Mid" -> "MarvelCollarLocation"=2 '0 is no, 1 is Left, 2 is right,3 Mid | D17: OK
A18: Equation | B18: 6 | C18: ="""ThermStat""="&'Model Data'!D12& " '0 no , 1 yes" -> "ThermStat"=1 '0 no , 1 yes | D18: OK
A19: Equation | B19: 7 | C19: ="""ABDType""="&'Model Data'!D15& " '0 no ABD, 1 is ABD8 with Collar, 2 ABD6 only, 3 ABD6 with Access Panel, 4 is ABD6 with Collar,5 is ABD6 collar access,6 is MBD only, 7 MBD with Collar" -> "ABDType"=0 '0 no ABD, 1 is ABD8 with Collar, 2 ABD6 only, 3 ABD6 with Access Panel, 4 is ABD6 with Collar,5 is ABD6 collar access,6 is MBD only, 7 MBD with Collar | D19: OK
A20: Equation | B20: 8 | C20: ="""AccessABDLocationLT""="&'Model Data'!D16& " '1 is Left, 2 is right" -> "AccessABDLocationLT"=2 '1 is Left, 2 is right | D20: OK
A21: Equation | B21: 9 | C21: ="""AccessABDLocationMid""="&'Model Data'!D17& " '1 is Left, 2 is right" -> "AccessABDLocationMid"=1 '1 is Left, 2 is right | D21: OK
A22: Equation | B22: 10 | C22: ="""AccessABDLocationRT""="&'Model Data'!D18& " '1 is Left, 2 is right" -> "AccessABDLocationRT"=2 '1 is Left, 2 is right | D22: OK
A23: Equation | B23: 11 | C23: ="""Ansultype""="&'Model Data'!D30& " '0 is no ansul,1 Left, 2 Left Both, 3 Right , 4 Right Both" -> "Ansultype"=1 '0 is no ansul,1 Left, 2 Left Both, 3 Right , 4 Right Both | D23: OK
A24: Equation | B24: 12 | C24: ="""AnsulDropQty""="&'Model Data'!D31& " 'Ansul Drop Qty" -> "AnsulDropQty"=1 'Ansul Drop Qty | D24: OK
A25: Equation | B25: 13 | C25: ="""KSAtype""="&'Model Data'!B45& " '13 ksa, 16 Ksa" -> "KSAtype"=13 '13 ksa, 16 Ksa | D25: OK
A26: Dimension | B26: HL@Sketch1 | C26: ='Model Data'!D4/1000 -> 2.4384 | D26: OK
A27: Dimension | B27: HW@Sketch1 | C27: ='Model Data'!D5/1000 -> 2.286 | D27: OK
A28: Dimension | B28: HH@PlaneBot | C28: ='Model Data'!D6/1000 -> 0.381 | D28: OK
A29: Dimension | B29: WidthFront@Sketch1 | C29: ='Model Data'!D7/1000 -> 0.1524 | D29: OK
A30: Dimension | B30: WidthBack@Sketch1 | C30: ='Model Data'!D10/1000 -> 0.1524 | D30: OK
A31: Dimension | B31: LC@SketchCollar | C31: ='Model Data'!D20/1000 -> 0.254 | D31: OK
A32: Dimension | B32: WC@SketchCollar | C32: ='Model Data'!D21/1000 -> 0.2032 | D32: OK
A33: Dimension | B33: HT@Surface-ExtrudeCollars | C33: ='Model Data'!D22/1000 -> 0.1016 | D33: OK
A34: Dimension | B34: DistC1ToLeft@SketchCollar | C34: ='Model Data'!D23/1000 -> 0.6096 | D34: OK
A35: Dimension | B35: Dist@SketchCollar | C35: ='Model Data'!D24/1000 -> 1.2192 | D35: OK
A36: Dimension | B36: LightToFront@Sketch1 | C36: ='Model Data'!D27/1000 -> 1.143 | D36: OK
A37: Dimension | B37: Ligth1ToLeft@Sketch1 | C37: ='Model Data'!D28/1000 -> 0.4064 | D37: OK
A38: Dimension | B38: DistLights@Sketch1 | C38: ='Model Data'!D29/1000 -> 0.8128 | D38: OK
A39: Stop | D39: OK
A40: Void | D40: - | G40: 1 collar:LT; 2 or 3 Collars: LT
...

Sheet ToSolidworksInstruction
A1: Command | B1: SolidWorks Object | C1: Value | D1: Status | E1: ConfigurationName | F1: Comment
A2: Start | B2: ComponentName | C2: FALSE or TRUE | D2: Ok / - | F2: Begin to handle this component or ignore it
B3: "MainAssembly" | E3: empty
B4: Sub assy-1@MainAssy/Part-1@Sub assy
B5: 3DUF00XXX-1@3D0XX00XX/3DUF01XXX-1@3DUF00XXX
B6: Part-1@Main assy
B7: "3D0X01XXX-3@3D0XX00XX"
A8: Dimension | B8: DimensionName | C8: New value. Unit is m or count number | D8: Ok / - | E8: empty or ConfigName | F8: Changes a dimension in the opened component
E9: empty means this component's current configuration
B10: "Dist@LPatternHole-V"
B12: "D1@Sketch1"
A13: ChangeMateAlign | B13: MateName | C13: FALSE or TRUE | D13: Ok / - | E13: Yes or No | F13: true=> (int)swMateAlign_e.swMateAlignALIGNED;false => (int)swMateAlign_e.swMateAlignANTI_ALIGNED
E14: whether to change
A16: ExcludeFromBOMComp | B16: ComponentName | C16: FALSE or TRUE | D16: Ok / - | E16: empty or ConfigName
E17: empty means this assembly's current configuration
B18: 2B0R25XXX-2@2B0R00LRX | E18: Normally should be empty
A19: AttributeCustom | B19: PropertyName | C19: New value | D19: Ok / - | F19: Changes the custom property of this component to "New value".
E20: empty
B21: "Material" | C21: "SW-Material"
A22: AttributeConfig | B22: PropertyName | C22: New value | D22: Ok / - | E22: empty or ConfigName | F22: Changes the Configuration specific property of this component’s configuration to "New value".
E23: empty means this component's current configuration
B24: "CodeModel" | C24: "special"
A25: Equation | B25: EquationSequenceNumber | C25: New value | D25: Ok / -
E26: empty or ConfigName
B27: 1 | C27: "PartCode"=3 ' Comment | E27: empty meas for all configurations
C29: "D1@Sketch1"=2 ' Comment
A30: SuppressFeature | B30: FeatureName "LPatternBtMullionPos" when open a part | C30: FALSE or TRUE | D30: Ok / - | E30: empty or ConfigName | F30: Changes the suppress status of specific feature of this component to "New value"..True suppress, false unsuppress. To suppress features inside a part. Want to suppress fearture for a specific config, bettter use active configuration command for the component first
B31: Cut-Extrude1@CvDrPl00-1@EleRiserCoverPlates/CvDrPl02-1@CvDrPl00, When open a sub assembly(EleRiserCoverPlates), and the feature is in a part(CvDrPl02-1) of a sub assemlby(CvDrPl00-1). | E31: empty means this component's current configuration
B32: Cut-LT@CvEbPl-2@EleRiserCoverPlates When open a sub assembly(EleRiserCoverPlates), and the feature(Cut-LT) is in a part(CvEbPl-2) of this subassembly
A33: SuppressComp | B33: ComponentName | C33: FALSE or TRUE | D33: Ok / - | F33: Changes the suppress status of specific component inside this component to "New value".True suppress, false unsuppress. To suppress components inside an assembly.
B34: 2B0R00LRX-1@2B0R00XXX/2B0R01NFX-1@2B0R00LRX | E34: empty
B35: 2B0R25XXX-2@2B0R00LRX
B36: Mate Name ( for example: Coincident22 )
B37: FOLDER ANME ( for example: BAFFLES)
A38: ChangeConfigOfSpecificComp | B38: ComponentName | C38: new configuration name | D38: Ok / - | E38: empty or | F38: Changes the configuration of specific component inside this component to new configuration name.True to exclude the comp from the BOM, false to inclded, and Enpty means keep the same as the old setting.
E39: FALSE or TRUE
B40: 2B0R25XXX-2@2B0R00LRX
A41: ComponentProp | B41: ActiveConfiguration | C41: 3D0XX00XE or Default | D41: Ok / - | F41: Changes the active configuration for this component to new value. When you want to change property of a component for a specific config, better use this command first.
E42: empty
A44: ComponentProp | B44: MaterialName | C44: New value | D44: Ok / - | F44: Changes the Material of this component to "New value".
...

Sheet Sheet1
C5: 0 | D5: LocType | E5: =1 -> 1 | F5: 1 | G5: 0 | H5: Hood Location, 0 sa, 1 LT, 2,Mid, 3 Rt
C6: 1 | D6: HL | E6: =126 -> 126 | F6: 126 | G6: 0 | H6: Hood Length
C7: 2 | D7: HW | E7: =37 -> 37 | F7: 37 | G7: 0 | H7: Hood Width
C8: 3 | D8: HF | E8: =9 -> 9 | F8: 9 | G8: 0 | H8: Hood Front Height
C9: 4 | D9: HB | E9: =38 -> 38 | F9: 38 | G9: 0 | H9: Hood Back Height
C10: 5 | D10: WBackAir | E10: =3 -> 3 | F10: 3 | G10: 0 | H10: Hood Back Air Space Width
C11: 6 | D11: EncType | E11: =0 -> 0 | F11: 0 | G11: 0 | H11: 0 L/F/R, 1 L/F, 2 F, 3 R/F
C12: 7 | D12: HEncPanel | E12: =51 -> 51 | F12: 51 | G12: 0 | H12: Enclosure Panel Height
C13: 8 | D13: DistEncToHF | E13: =11 -> 11 | F13: 11 | G13: 0 | H13: Enclosure Panel To Hood Front
C14: 9 | D14: QtyCollar | E14: =1 -> 1 | F14: 1 | G14: 0 | H14: Collar Qty, 0,1,2,3
C15: 10 | D15: LCollar | E15: =11 -> 11 | F15: 11 | G15: 0 | H15: Collar Length
C16: 11 | D16: WCollar | E16: =8 -> 8 | F16: 8 | G16: 0 | H16: Collar Width
C17: 12 | D17: HCollar | E17: =3 -> 3 | F17: 3 | G17: 0 | H17: Collar Height
C18: 13 | D18: DistCollarToBkair | E18: =2 -> 2 | F18: 2 | G18: 0 | H18: Collar To Back
C19: 14 | D19: LightType | E19: =1 -> 1 | F19: 1 | G19: 0 | H19: Light type, 0 is no, 1 is Led
C20: 15 | D20: CJFanSide | E20: =2 -> 2 | F20: 2 | G20: 0 | H20: 1 is cj fan on left, 2 is cj fan on right
C21: 16 | D21: JetFanType | E21: =6 -> 6 | F21: 6 | G21: 0 | H21: fan type, 4 is K4 fan, 6 is K6 fan
C22: 17 | D22: Ansultype | E22: =1 -> 1 | F22: 1 | G22: 0 | H22: 1 ansul Lt ,2 ansul Lt and Detect Both, 3 ansul Rt, 4 Ansul Rt and Detect Both
C23: 18 | D23: AnsulMidQty | E23: =7 -> 7 | F23: 7 | G23: 0
C24: 19 | D24: AnsulFrontQty | E24: =2 -> 2 | F24: 2 | G24: 0
C25: 20 | D25: FireCab | E25: =1 -> 1 | F25: 1 | G25: 0 | H25: Fire Cab ,0 is no, 1 is Yes
C26: 21 | D26: LabelQty | E26: =7 -> 7 | F26: 7 | G26: 0
C27: 22 | D27: LeftSideEndType | E27: =2 -> 2 | F27: 2 | G27: 0 | H27: 1 is cj, 2 is Notch, 3 is slope
C28: 23 | D28: RightSideEndType | E28: =1 -> 1 | F28: 1 | G28: 0 | H28: 1 is CJ, 2 is Full
C29: 24 | D29: KSAwidthOccupied | E29: =497 -> 497 | F29: 497 | G29: 0
C30: 25 | D30: KSAtype | E30: =13 -> 13 | F30: 13 | G30: 0 | H30: Ksa Type, 13 or 16
C31: 26 | D31: SideAirLT | E31: =0 -> 0 | F31: 0 | G31: 0 | H31: Side air space Lt, 0 is no, 1 is wall
C32: 27 | D32: SideAirRT | E32: =0 -> 0 | F32: 0 | G32: 0 | H32: Side air space Rt, 0 is no, 1 is wall
