Workbook
Name CheckBacthPrintWithBOM: 'Project Info'!$H$2
Name checkBoxGA: 'Project Info'!#REF!
Name checkBoxMM: 'Project Info'!#REF!
Name CheckIncludeFlat: 'Project Info'!$C$2
Name CheckInitialize: 'Project Info'!#REF!
Name CheckInitialize: 'Project Info'!$C$1
Name CheckToday: 'Project Info'!#REF!
Name CKBxDXF: 'Project Info'!$H$1
Name CkBxEdrw: 'Project Info'!$G$1
Name CKBxJPG: 'Project Info'!$J$2
Name CkBxPDF: 'Project Info'!$G$2
Name ComboBoxPaperSize: 'Project Info'!$L$1
Name ComboBoxProjectAngle: 'Project Info'!$P$1
Name ComboBoxUnit: 'Project Info'!$K$2
Name ComboBoxUnitSystem: 'Project Info'!$K$1
Name ComboExcelSheetName: 'Project Info'!$M$1
Name ComPrinter: 'Project Info'!$M$2
Name OptionAssembly: 'Project Info'!#REF!
Name OptionAssembly: 'Project Info'!$I$1
Name OptionAssySetBA: 'Project Info'!#REF!
Name OptionAssySetBA: 'Project Info'!#REF!
Name OptionEXcel: 'Project Info'!#REF!
Name OptionEXcel: 'Project Info'!#REF!
Name OptionInPathName: 'Project Info'!$N$1
Name OptionMacro: 'Project Info'!#REF!
Name OptionMacro: 'Project Info'!#REF!
Name OptionOneFile: 'Project Info'!#REF!
Name OptionOneFile: 'Project Info'!$I$2
Name OptionOneFileSetBA: 'Project Info'!#REF!
Name OptionOneFileSetBA: 'Project Info'!#REF!
Name OptionOpenInWindwos: 'Project Info'!$N$2
Name OptionOutPath: 'Project Info'!#REF!
Name OptionOutPath: 'Project Info'!#REF!
Name OptionOutToSameFolder: 'Project Info'!#REF!
Name OptionOutToSameFolder: 'Project Info'!#REF!
Name OptionPlumbing: 'Project Info'!#REF!
Name OptionPlumbing: 'Project Info'!$J$1
Name TextBranchLocation: 'Project Info'!$B$2
Name TextBy: 'Project Info'!$C$5
Name TextCheckedBy: 'Project Info'!$C$9
Name TextCheckList: 'Project Info'!$T$1
Name TextCode: 'Project Info'!$G$6
Name TextCode: 'Project Info'!$G$6
Name TextDate: 'Project Info'!$G$7
Name TextDxfScale: 'Project Info'!#REF!
Name TextDxfScale: 'Project Info'!$B$1
Name TextHemK14GASetBA: 'Project Info'!#REF!
Name TextHemK14GASetBA: 'Project Info'!#REF!
Name TextHemK16GASetBA: 'Project Info'!#REF!
Name TextHemK16GASetBA: 'Project Info'!#REF!
Name TextHemK18GASetBA: 'Project Info'!#REF!
Name TextHemK18GASetBA: 'Project Info'!#REF!
Name TextHemK20GASetBA: 'Project Info'!#REF!
Name TextHemK20GASetBA: 'Project Info'!#REF!
Name TextInPathName: 'Project Info'!$E$1
Name TextInsideBendRadius14GASetBA: 'Project Info'!#REF!
Name TextInsideBendRadius14GASetBA: 'Project Info'!#REF!
Name TextInsideBendRadius16GASetBA: 'Project Info'!#REF!
Name TextInsideBendRadius16GASetBA: 'Project Info'!#REF!
Name TextInsideBendRadius18GASetBA: 'Project Info'!#REF!

Sheet Project Info
B1: 1 | C1: False | E1: C:\Users\jluo\Documents\SolidworksTemplates-2023Edit\Macros | G1: FALSE | H1: True | I1: True | J1: False | K1: IPS | L1: Letter | M1: Hood Quality | N1: false | P1: First Angle Projection | Q1: JOB NAME: | R1: SERIAL No: | S1: Project Code: | T1: =LEFT(TextJobName,(Q2-(R2-S2))) -> Standard Product
B2: Mississauga-Canada | C2: False | E2: K:\DigitalFactory\Content\StandardProduct\ABD\10106 | G2: True | H2: True | I2: False | J2: True | K2: mm | M2: KONICA MINOLTA Universal V4 PCL | N2: true | Q2: =LEN(TextJobName) -> 16 | R2: =LEN(TextSerialNo) -> 0 | S2: =LEN(TextCode) -> 0 | T2: =LEN(T1) -> 16 | V2: K:\DigitalFactory\
B4: JOB NAME: | C4: Standard Product | I4: Project Status: | J4: CNC Program
B5: Engineer: | C5: Mujeeb | F5: ASM PDF: | H5: ABD Assembly-10106LA | I5: EASM: | J5: ABD Assembly-10106LA
B6: SERIAL No: | F6: Project Code:
B7: MODEL: | C7: ABD | F7: DATE: | G7: 2025-04-04
B9: CHECKED BY: | C9: German
B10: QUANTITY: | C10: 1 | E10: SHIP DATE:
C13: SHEAR SIZE (inch)
B14: MATERIAL | C14: X (GRAIN ) | D14: Y | E14: PART DESCRIPTION | F14: QTY. | G14: CNC No. | H14: PART No. | I14: Weight Lbs | J14: SQ. FT | K14: Weight Lbs 1 | M14: In both job folder and Library | O14: QtyIn1Unit | P14: RadanProjectMtName | Q14: RadanMThickness | S14: UK Labels
B15: 18 GA S/S - #4 | C15: 11.754 | D15: 7.734 | E15: ABD Front | F15: =O15*TextQTY -> 1 | H15: 53280RX-106AL | I15: =K15*F15 -> 1.27 | J15: =C15*D15*F15/144 -> 0.63128775 | K15: 1.27 | O15: 1 | P15: =IF(LEN(B15)>1,RIGHT(B15,LEN(B15)-6),"") -> S/S - #4 | Q15: =_xlfn.XLOOKUP(LEFT(B15,5),'Change K Factors'!$A$3:$A$50,'Change K Factors'!$E$3:$E$50,'Change K Factors'!$E$4) -> 1.22
B16: 18 GA S/S - #4 | C16: 11.754 | D16: 7.734 | E16: ABD Back | F16: =O16*TextQTY -> 1 | H16: 53280SX-106 | I16: =K16*F16 -> 1.27 | J16: =C16*D16*F16/144 -> 0.63128775 | K16: 1.27 | O16: 1 | P16: =IF(LEN(B16)>1,RIGHT(B16,LEN(B16)-6),"") -> S/S - #4 | Q16: =_xlfn.XLOOKUP(LEFT(B16,5),'Change K Factors'!$A$3:$A$50,'Change K Factors'!$E$3:$E$50,'Change K Factors'!$E$4) -> 1.22
B17: 18 GA S/S - #4 | C17: 1.024 | D17: 1.772 | E17: ABD Damper shaft Linkage | F17: =O17*TextQTY -> 2 | H17: 53283BX | I17: =K17*F17 -> 0.06 | J17: =C17*D17*F17/144 -> 0.025201778 | K17: 0.03 | O17: 2 | P17: =IF(LEN(B17)>1,RIGHT(B17,LEN(B17)-6),"") -> S/S - #4 | Q17: =_xlfn.XLOOKUP(LEFT(B17,5),'Change K Factors'!$A$3:$A$50,'Change K Factors'!$E$3:$E$50,'Change K Factors'!$E$4) -> 1.22
B18: 18 GA S/S - #4 | C18: 4.724 | D18: 0.748 | E18: DAMPER Straight Linkage | F18: =O18*TextQTY -> 1 | H18: 53285JX | I18: =K18*F18 -> 0.05 | J18: =C18*D18*F18/144 -> 0.024538556 | K18: 0.05 | O18: 1 | P18: =IF(LEN(B18)>1,RIGHT(B18,LEN(B18)-6),"") -> S/S - #4 | Q18: =_xlfn.XLOOKUP(LEFT(B18,5),'Change K Factors'!$A$3:$A$50,'Change K Factors'!$E$3:$E$50,'Change K Factors'!$E$4) -> 1.22
B19: 18 GA S/S - #4 | C19: 15.145 | D19: 7.24 | E19: ABD COVER PLUS 10 | F19: =O19*TextQTY -> 1 | H19: 53286PX-10L | I19: =K19*F19 -> 1.54 | J19: =C19*D19*F19/144 -> 0.76145694 | K19: 1.54 | O19: 1 | P19: =IF(LEN(B19)>1,RIGHT(B19,LEN(B19)-6),"") -> S/S - #4 | Q19: =_xlfn.XLOOKUP(LEFT(B19,5),'Change K Factors'!$A$3:$A$50,'Change K Factors'!$E$3:$E$50,'Change K Factors'!$E$4) -> 1.22
B20: 18 GA S/S - #4 | C20: 2.362 | D20: 10.533 | E20: Vane Bracket | F20: =O20*TextQTY -> 2 | H20: 53288AX-10 | I20: =K20*F20 -> 0.7 | J20: =C20*D20*F20/144 -> 0.34554092 | K20: 0.35 | O20: 2 | P20: =IF(LEN(B20)>1,RIGHT(B20,LEN(B20)-6),"") -> S/S - #4 | Q20: =_xlfn.XLOOKUP(LEFT(B20,5),'Change K Factors'!$A$3:$A$50,'Change K Factors'!$E$3:$E$50,'Change K Factors'!$E$4) -> 1.22
B21: 18 GA S/S - #4 | C21: 11.85 | D21: 7.638 | E21: ABD Right | F21: =O21*TextQTY -> 1 | H21: 54102BX-106 | I21: =K21*F21 -> 1.27 | J21: =C21*D21*F21/144 -> 0.62854375 | K21: 1.27 | O21: 1 | P21: =IF(LEN(B21)>1,RIGHT(B21,LEN(B21)-6),"") -> S/S - #4 | Q21: =_xlfn.XLOOKUP(LEFT(B21,5),'Change K Factors'!$A$3:$A$50,'Change K Factors'!$E$3:$E$50,'Change K Factors'!$E$4) -> 1.22
B22: 18 GA S/S - #4 | C22: 11.85 | D22: 7.638 | E22: ABD LEFT | F22: =O22*TextQTY -> 1 | H22: 54102SX-106 | I22: =K22*F22 -> 1.27 | J22: =C22*D22*F22/144 -> 0.62854375 | K22: 1.27 | O22: 1 | P22: =IF(LEN(B22)>1,RIGHT(B22,LEN(B22)-6),"") -> S/S - #4 | Q22: =_xlfn.XLOOKUP(LEFT(B22,5),'Change K Factors'!$A$3:$A$50,'Change K Factors'!$E$3:$E$50,'Change K Factors'!$E$4) -> 1.22
B23: 18 GA S/S - #4 | C23: 10.1 | D23: 6.484 | E23: Damper Blade | F23: =O23*TextQTY -> 2 | H23: 54103BX-10106 | I23: =K23*F23 -> 1.84 | J23: =C23*D23*F23/144 -> 0.90956111 | K23: 0.92 | O23: 2 | P23: =IF(LEN(B23)>1,RIGHT(B23,LEN(B23)-6),"") -> S/S - #4 | Q23: =_xlfn.XLOOKUP(LEFT(B23,5),'Change K Factors'!$A$3:$A$50,'Change K Factors'!$E$3:$E$50,'Change K Factors'!$E$4) -> 1.22
B26: =B14 -> MATERIAL | C26: =I14 -> Weight Lbs | D26: =J14 -> SQ. FT
B27: 18 GA S/S - #4 | C27: =SUBTOTAL(9,I15:I23) -> 9.27 | D27: =SUBTOTAL(9,J15:J23) -> 4.5859623

Sheet Hood Quality
C3: Hood Quality Checklist
C4: Project Name: | F4: =TextJobName -> Standard Product
C5: Engineer: | F5: =TextBy -> Mujeeb | I5: Description: | M5: ='Project Info'!H5 -> ABD Assembly-10106LA
C6: Drawing & Item #: | F6: =TextSerialNo | I6: Ship Date: | M6: =TextShipDate | Z6: Design
C7: Check the following: | F7: ( "X"complies , "C" corrected or reworked, "N/A" not applicable ) | Z7: BOM
E9: No Scratches | K9: Hood cleaned and vacuumed | Z9: CNC Program
Z10: Released
E11: No dents | K11: Grease cup installed | Z11: Punch
Z12: Press Brake
E13: No steel imperfections | K13: CJ fan tested and calibrated | Z13: Weld
Z14: Assembly
E15: Brake press quality | K15: Correct Static pressure tag attached (CJ models only) | Z15: Crate
Z16: Shipped
E17: Capture jet holes present and match drawing | K17: Location/orientation of nozzles correct
E19: Weld Quality in general and Brackets if applicable | K19: Ansul allows clearance to remove cassettes (UV models only)
E21: Caulking properly applied | K21: Light fixtures installed/tested
E23: Welding Dampers Complete and Check for Pinholes | K23: Fire protection correctly installed
E25: Polishing Completed | K25: Inspection label attached to hood & signed
E27: Fire damper installed | I27: Items below inspected/verified by crating operator
K28: Customer information package inside hood
E29: No Scratches and No dents
K30: UV lights packed/included
E31: Unit passed Dielectric Voltage Test
K32: Filter removal tool included
E33: UV testing completed & test sheet attached to hood (UV models only)
K34: Filters installed and/or packed
E35: Marvel testing completed & test sheet attached to hood
K36: All comonents secured within crate and Photo taken
E37: Labels applied and verified
E40: Operation | F40: Name | G40: Finish Date | H40: Hours | K40: Checked by | M40: Lead Hands
E41: CNC | K41: CNC/BP
E42: BP | K42: WELDING
E43: WELDING | K43: ASSEMBLY
E44: ANSUL | K44: ELECTRICAL
E45: ASSEMBLY
E46: ELECTRICAL | K46: ENGINEER
E47: CRATING
E49: rev D JUNE/2024

Sheet KVE WW or UV Stock Parts
B3: DXF>>>>>>>>I:\engineering\PTC_data\wo\KVE-WW-STD-PARTS
B4: JOB NAME: | C4: ='Project Info'!C4 -> Standard Product | J4: NOTE: TOTAL NUMBER IS FOR ALL THE HOODS IN THE JOB
B5: Engineer: | C5: ='Project Info'!C5 -> Mujeeb | J5: MANUALLY INPUT BY ENGINEER
B6: SERIAL No: | C6: ='Project Info'!C6 | F6: Project Code: | G6: ='Project Info'!G6 | J6: TOTAL NUMBER OF HOODS | M6: 1
B7: MODEL: | C7: ='Project Info'!C7 -> ABD | F7: DATE: | G7: ='Project Info'!G7 -> 2025-04-04 | J7: TOTAL NUMBER OF CASSETTES | M7: 2
B9: CHECKED BY: | C9: German
B10: QUANTITY: | E10: SHIP DATE: | G10: ='Project Info'!G10 | J10: TOTAL NUMBER OF 13" KSA | M10: 14
B11: Drawings are in KVE WW UV Binder | J11: TOTAL NUMBER OF Doors | M11: 2
C13: SHEAR SIZE (inch) | I13: Total | J13: Total | K13: Unit | L13: Comment
B14: MATERIAL | C14: X (GRAIN ) | D14: Y | E14: PART DESCRIPTION | F14: QTY. | G14: CNC No. | H14: PART No. | I14: Weight Lbs | J14: SQ. FT | K14: Weight Lbs
B15: 16 GA S/S - #4 | C15: 2.936 | D15: 5.614 | E15: CA-KVE WW-Manifold Bracket-Front | F15: =3*M6 -> 3 | H15: 53245AX | I15: =K15*F15 -> 0.87 | J15: =C15*D15*F15/144 -> 0.34338967 | K15: 0.29 | L15: KVE WW & UV
B16: 16 GA S/S - #4 | C16: 4.305 | D16: 1.969 | E16: CA-KVE WW-Manifold Bracket-Back | F16: =3*M6 -> 3 | H16: 53246AX | I16: =K16*F16 -> 0.45 | J16: =C16*D16*F16/144 -> 0.17659469 | K16: 0.15 | L16: KVE WW & UV
B17: 16 GA S/S - #4 | C17: 1.969 | D17: 1.462 | E17: CA-KVE WW-Manifold Clamp Bracket | F17: =9*M6 -> 9 | H17: 53247XX | I17: =K17*F17 -> 0.45 | J17: =C17*D17*F17/144 -> 0.17991737 | K17: 0.05 | L17: KVE WW & UV
B18: 16 GA S/S - #4 | C18: 14.311 | D18: 8.965 | E18: CA-KVE WW UV-UV Cassette Support - Right | F18: =M6*M7 -> 2 | H18: 53237XX | I18: =K18*F18 -> 4.46 | J18: =C18*D18*F18/144 -> 1.7819183 | K18: 2.23 | L18: KVE WW UV
B19: 16 GA S/S - #4 | C19: 14.311 | D19: 8.965 | E19: CA-KVE WW UV-UV Cassette Support - Left | F19: =M6*M7 -> 2 | H19: 53238XX | I19: =K19*F19 -> 4.46 | J19: =C19*D19*F19/144 -> 1.7819183 | K19: 2.23 | L19: KVE WW UV
B20: 16 GA S/S - #4 | C20: 1.496 | D20: 5.073 | E20: CA-KVE WW UV-UV Cassette Hanger | F20: =M6*2*M7 -> 4 | H20: 53265XX | I20: =K20*F20 -> 0.52 | J20: =C20*D20*F20/144 -> 0.21081133 | K20: 0.13 | L20: KVE WW UV
B22: 18 GA S/S - #4 | C22: 6.224 | D22: 9.147 | E22: CA-KVE WW-UV-Muffin Fan Mount Bracket | F22: =M6*M7 -> 2 | H22: 50033XX | I22: =K22*F22 -> 1.6 | J22: =C22*D22*F22/144 -> 0.79070733 | K22: 0.8 | L22: KVE WW UV
B23: 18 GA S/S - #4 | C23: 3.107 | D23: 3.875 | E23: CA-KVE WW-Ansul Detect Channel Side-RT | F23: =M6 -> 1 | H23: 53209XA | I23: =K23*F23 -> 0.17 | J23: =C23*D23*F23/144 -> 0.083608507 | K23: 0.17 | L23: KVE WW & UV
B24: 18 GA S/S - #4 | C24: 3.107 | D24: 3.875 | E24: CA-KVE WW-Ansul Detect Channel Side-LT | F24: =M6 -> 1 | H24: 53209XB | I24: =K24*F24 -> 0.17 | J24: =C24*D24*F24/144 -> 0.083608507 | K24: 0.17 | L24: KVE WW & UV
B25: 18 GA S/S - #4 | C25: 7.049 | D25: 7.701 | E25: CA-KVE WW UV-UV Cassette Access Mullion-Mid | F25: =M6*IF(M7>0,M7-1,0) -> 1 | H25: 53220XX | I25: =K25*F25 -> 0.76 | J25: =C25*D25*F25/144 -> 0.37697465 | K25: 0.76 | L25: KVE WW UV
B26: 18 GA S/S - #4 | C26: 1.092 | D26: 6.937 | E26: CA-KVE WW UV-UV Cassette Access Mullion-Clip Hem | F26: =M6*2*M7 -> 4 | H26: 53223XX | I26: =K26*F26 -> 0.44 | J26: =C26*D26*F26/144 -> 0.21042233 | K26: 0.11 | L26: KVE WW UV
B27: 18 GA S/S - #4 | C27: 6.034 | D27: 13.853 | E27: CA-KVE WW-KSA Door Divider-Cover | F27: =M6*(M11-1) -> 1 | H27: 53233XX-338 | I27: =K27*F27 -> 1.17 | J27: =C27*D27*F27/144 -> 0.58047918 | K27: 1.17 | L27: KVE WW & UV
B28: 18 GA S/S - #4 | C28: 2.268 | D28: 3.047 | E28: CA-KVE WW UV-KSA Panel Switch Activator | F28: =2*M6*IF(M7>0,1,0) -> 2 | H28: 53239XX | I28: =K28*F28 -> 0.2 | J28: =C28*D28*F28/144 -> 0.0959805 | K28: 0.1 | L28: KVE WW UV
B29: 18 GA S/S - #4 | C29: 10.721 | D29: 15.427 | E29: CA-KVE WW UV-KSA Door SW Cover Body-LT | F29: =M6*IF(M7>0,1,0) -> 1 | H29: 53240AX-13 | I29: =K29*F29 -> 2.32 | J29: =C29*D29*F29/144 -> 1.1485616 | K29: 2.32 | L29: KVE WW UV
B30: 18 GA S/S - #4 | C30: 10.721 | D30: 15.427 | E30: CA-KVE WW UV-KSA Door SW Cover Body-RT | F30: =M6*IF(M7>0,1,0) -> 1 | H30: 53240XX-13 | I30: =K30*F30 -> 2.32 | J30: =C30*D30*F30/144 -> 1.1485616 | K30: 2.32 | L30: KVE WW UV
B31: 18 GA S/S - #4 | C31: 4.402 | D31: 8.931 | E31: CA-KVE WW UV-KSA Door SW Cover Side-LT | F31: =M6*IF(M7>0,1,0) -> 1 | H31: 53241AX-13 | I31: =K31*F31 -> 0.55 | J31: =C31*D31*F31/144 -> 0.27301571 | K31: 0.55 | L31: KVE WW UV
B32: 18 GA S/S - #4 | C32: 4.402 | D32: 8.931 | E32: CA-KVE WW UV-KSA Door SW Cover Side-RT | F32: =M6*IF(M7>0,1,0) -> 1 | H32: 53241XX-13 | I32: =K32*F32 -> 0.55 | J32: =C32*D32*F32/144 -> 0.27301571 | K32: 0.55 | L32: KVE WW UV
B33: 18 GA S/S - #4 | C33: 3.307 | D33: 6.953 | E33: CA-KVE WW-KSA Door SW Plate-Side | F33: =2*M6*IF(M7>0,1,0) -> 2 | H33: 53242XX | I33: =K33*F33 -> 0.64 | J33: =C33*D33*F33/144 -> 0.31935515 | K33: 0.32 | L33: KVE WW UV
B34: 18 GA S/S - #4 | C34: 8.228 | D34: 12.136 | E34: CA-KVE WW-KSA Door Divider-Body | F34: =M6*(M11-1) -> 1 | H34: 53243XX-13 | I34: =K34*F34 -> 1.4 | J34: =C34*D34*F34/144 -> 0.69343756 | K34: 1.4 | L34: KVE WW & UV
B35: 18 GA S/S - #4 | C35: 5.11 | D35: 8.931 | E35: CA-KVE WW-KSA Door Divider-Body-Side | F35: =M6*(M11-1) -> 1 | H35: 53244XX-13 | I35: =K35*F35 -> 0.64 | J35: =C35*D35*F35/144 -> 0.31692646 | K35: 0.64 | L35: KVE WW & UV
B36: 18 GA S/S - #4 | C36: 1.756 | D36: 5.836 | E36: CA-KVE WW-KSA Door Divider-Body-Cap | F36: =M6*(M11-1) -> 1 | H36: 53262XX | I36: =K36*F36 -> 0.14 | J36: =C36*D36*F36/144 -> 0.071166778 | K36: 0.14 | L36: KVE WW & UV
B37: 18 GA S/S - #4 | C37: 3.402 | D37: 5.836 | E37: CA-KVE WW-KSA Door Body Cap-Side | F37: =2*M6*IF(M7>0,1,0) -> 2 | H37: 53263XX | I37: =K37*F37 -> 0.56 | J37: =C37*D37*F37/144 -> 0.275751 | K37: 0.28 | L37: KVE WW UV
B38: 18 GA S/S - #4 | C38: 1.969 | D38: 3.144 | E38: CA-KVE WW UV-Filter Switch Bracket | F38: =2*M6*IF(M7>0,1,0) -> 2 | H38: 53266XA | I38: =K38*F38 -> 0.18 | J38: =C38*D38*F38/144 -> 0.085979667 | K38: 0.09 | L38: KVE WW UV
B39: 18 GA S/S - #4 | C39: 1.969 | D39: 2.306 | E39: CA-KVE WW UV-Filter Switch Bracket | F39: =M6*(M7+M10)*IF(M7>0,1,0) -> 16 | H39: 53266XX | I39: =K39*F39 -> 0.96 | J39: =C39*D39*F39/144 -> 0.50450156 | K39: 0.06 | L39: KVE WW UV
B40: 18 GA S/S - #4 | C40: 8.646 | D40: 6.189 | E40: CA-KVE WW UV-Cassette Access Switch Chase | F40: =M6*M7 -> 2 | H40: 53248XXA | I40: =K40*F40 -> 1.5 | J40: =C40*D40*F40/144 -> 0.74319575 | K40: 0.75 | L40: KVE WW UV
B41: 18 GA S/S - #4 | C41: 7.15 | D41: 4.681 | E41: CA-KVE WW UV-Cassette Access Switch Chase Top | F41: =M6*M7 -> 2 | H41: 53249XX | I41: =K41*F41 -> 0.94 | J41: =C41*D41*F41/144 -> 0.46484931 | K41: 0.47 | L41: KVE WW UV
B42: 18 GA S/S - #4 | C42: 8.189 | D42: 4.181 | E42: CA-KVE WW UV-Cassette Access Switch Chase Tab | F42: =M6*M7 -> 2 | H42: 53250XX | I42: =K42*F42 -> 0.96 | J42: =C42*D42*F42/144 -> 0.47553068 | K42: 0.48 | L42: KVE WW UV
B43: 18 GA S/S - #4 | C43: 2.047 | D43: 1.378 | E43: CA-KVE WW UV-Filter Switch Chase Tab | F43: =(M7*2)+IF(M7>0,(M6*2),0) -> 6 | H43: 53253XX | I43: =K43*F43 -> 0.24 | J43: =C43*D43*F43/144 -> 0.11753192 | K43: 0.04 | L43: KVE WW UV
B46: =B14 -> MATERIAL | C46: =I14 -> Weight Lbs | D46: =J14 -> SQ. FT
B47: 16 GA S/S - #4 | C47: =SUBTOTAL(9,I15:I20) -> 11.21 | D47: =SUBTOTAL(9,J15:J20) -> 4.4745496
...

Sheet CM HOOD STD PARTS
D3: ="CM HOOD STD PARTS of " &TextJobName&" "&TextCode -> CM HOOD STD PARTS of Standard Product | K3: Qty34Door= | L3: 2 | N3: QtyTotalDoor= | O3: =SUM(L3:L5) -> 3
B4: SHEAR SIZE | K4: Qty28Door= | L4: 1 | N4: QtyCollars= | O4: 1
A5: MATERIAL | B5: GRAIN | D5: PART DESCRIPTION | E5: QTY. | F5: CNC No. | G5: PART No. | K5: Qty22Door= | L5: 0
A6: 12GA_S/S_#304-4 | B6: 0.5 | C6: 6.454 | D6: BRACE FRONT LIP POD ,CM-B | E6: 4 | G6: 005-A8K-0000 | H6: =4.427*I6 -> 0.39683136 | I6: =B6*C6*E6/144 -> 0.089638889
A8: 18GA_S/S_#304-4 | B8: 35.188 | C8: 17.814 | D8: FRONT ACCESS DOOR CM-B .34 | E8: =L3 -> 2 | G8: 265-A8B-0032 | H8: =2.016*I8 -> 17.551493 | I8: =B8*C8*E8/144 -> 8.7060977
A9: 18GA_S/S_#304-4 | B9: 33.25 | C9: 2.915 | D9: DIVIDER ADJ BAFFLE ,DOOR CM-B,34 | E9: =L3 -> 2 | G9: 265-A8D-0032 | H9: =2.016*I9 -> 2.713865 | I9: =B9*C9*E9/144 -> 1.3461632
A10: 18GA_S/S_#304-4 | B10: 37.113 | C10: 4.178 | D10: DIVIDER ,DOOR CM-B,34 | E10: =L3 -> 2 | G10: 265-A8C-0032 | H10: =2.016*I10 -> 4.3416272 | I10: =B10*C10*E10/144 -> 2.1535849
A11: 18GA_S/S_#304-4 | B11: 29.188 | C11: 17.814 | D11: FRONT ACCESS DOOR CM-B .28 | E11: =$L$4 -> 1 | G11: 265-A8B-0031 | H11: =2.016*I11 -> 7.2793704 | I11: =B11*C11*E11/144 -> 3.6107988
A12: 18GA_S/S_#304-4 | B12: 27.25 | C12: 2.915 | D12: DIVIDER ADJ BAFFLE ,DOOR CM-B,28 | E12: =$L$4 -> 1 | G12: 265-A8D-0031 | H12: =2.016*I12 -> 1.1120725 | I12: =B12*C12*E12/144 -> 0.55162326
A13: 18GA_S/S_#304-4 | B13: 31.113 | C13: 4.178 | D13: DIVIDER ,DOOR CM-B,28 | E13: =$L$4 -> 1 | G13: 265-A8C-0031 | H13: =2.016*I13 -> 1.8198616 | I13: =B13*C13*E13/144 -> 0.90270913
A14: 18GA_S/S_#304-4 | B14: 23.188 | C14: 17.814 | D14: FRONT ACCESS DOOR CM-B .22 | E14: =L5 -> 0 | G14: 265-A8B-0030 | H14: =2.016*I14 -> 0 | I14: =B14*C14*E14/144 -> 0
A15: 18GA_S/S_#304-4 | B15: 21.25 | C15: 2.915 | D15: DIVIDER ADJ BAFFLE ,DOOR CM-B,22 | E15: =L5 -> 0 | G15: 265-A8D-0030 | H15: =2.016*I15 -> 0 | I15: =B15*C15*E15/144 -> 0
A16: 18GA_S/S_#304-4 | B16: 25.113 | C16: 4.178 | D16: DIVIDER ,DOOR CM-B,22 | E16: =L5 -> 0 | G16: 265-A8C-0030 | H16: =2.016*I16 -> 0 | I16: =B16*C16*E16/144 -> 0
A17: 18GA_S/S_#304-4 | B17: 0.5 | C17: 0.992 | D17: CLIP RETAINER POD DOOR CM-B | E17: =2*O3 -> 6 | G17: 265-A8F-0000 | H17: =2.016*I17 -> 0.041664 | I17: =B17*C17*E17/144 -> 0.020666667
A18: 18GA_S/S_#304-4 | B18: 6.263 | C18: 4.275 | D18: BRACKET INTERMEDIATE REAR POD CM-B | E18: =O3-1 -> 2 | G18: 265-A8H-0000 | H18: =2.016*I18 -> 0.7496811 | I18: =B18*C18*E18/144 -> 0.37186563
A19: 18GA_S/S_#304-4 | B19: 3.514 | C19: 2.916 | D19: BRACKET TOP MANIFOLD POD CM-B | E19: 2 | G19: 265-A8M-0000 | H19: =2.016*I19 -> 0.28691107 | I19: =B19*C19*E19/144 -> 0.142317
A20: 18GA_S/S_#304-4 | B20: 5.18 | C20: 2.437 | D20: CLIP MIDDLE,POD ACCESS DOOR CM-B | E20: =O3-1 -> 2 | G20: 265-A8I-0000 | H20: =2.016*I20 -> 0.35346248 | I20: =B20*C20*E20/144 -> 0.17532861
A21: 18GA_S/S_#304-4 | B21: 1.519 | C21: 12.875 | D21: DIVIDER POD SPRAY BAFFLE | E21: =O3-1 -> 2 | G21: 265-A8J-0000 | H21: =2.016*I21 -> 0.5475995 | I21: =B21*C21*E21/144 -> 0.27162674
A22: 18GA_S/S_#304-4 | B22: 2.524 | C22: 2.437 | D22: CLIP END,POD ACCESS DOOR CM-B | E22: 2 | G22: 265-A8L-0000 | H22: =2.016*I22 -> 0.17222766 | I22: =B22*C22*E22/144 -> 0.085430389
A23: 18GA_S/S_#304-4 | B23: 5 | C23: 1.038 | D23: VOLUME DAMPER BRACKET CM-B | E23: =2*O4 -> 2 | G23: 265-VDA-0000 | H23: =2.016*I23 -> 0.14532 | I23: =B23*C23*E23/144 -> 0.072083333
A25: MATERIAL | B25: SQ. FT | C25: LBS
A26: 12GA_S/S_#304-4 | B26: =SUM(I6) -> 0.089638889 | C26: =B26*3.5 -> 0.31373611
A27: 18GA_S/S_#304-4 | B27: =SUM(I8:I23) -> 18.410295 | C27: =B27*2.016 -> 37.115155

Sheet Change K Factors
A1: Change K Factors
A2: MaterialGauges | B2: SheetMetalKFactor | C2: HemKFactor | D2: InsideBendRadiusMM | E2: MaterialThicknessMM
A3: 20 GA | B3: 0.089 | C3: 0.65 | D3: 1 | E3: 0.9
A4: 18 GA | B4: 0.089 | C4: 0.65 | D4: 1 | E4: 1.22
A5: 16 GA | B5: 0.124 | C5: 0.65 | D5: 1 | E5: 1.51
A6: 14 GA | B6: 0.34 | C6: 0.65 | D6: 1 | E6: 1.91
A7: 12 GA | B7: 0.34 | C7: 0.65 | D7: 1 | E7: 2.68
A8: 10 GA | B8: 0.34 | C8: 0.65 | D8: 1 | E8: 3.175
A9: 0.95mm | B9: 0.089 | C9: 0.65 | D9: 1 | E9: 0.95
A10: 1.00mm | B10: 0.182 | C10: 0.65 | D10: 0.5 | E10: 1
A11: 1.20mm | B11: 0.256 | C11: 0.65 | D11: 0.5 | E11: 1.2
A12: 1.25mm | B12: 0.256 | C12: 0.65 | D12: 0.5 | E12: 1.2
A13: 1.35mm | B13: 0.26 | C13: 0.65 | D13: 0.5 | E13: 1.35
A14: 1.50mm | B14: 0.206 | C14: 0.65 | D14: 0.5 | E14: 1.5
... A21: 12.0mm | B21: 0.209 | C21: 0.65 | D21: 0.5 | E21: 12

Sheet Change K Factors Material Data
A2: For Stainless Steel | H2: For Cold Roll and alumalize
A3: Change K Factors | H3: Change K Factors
A4: MaterialGauges | B4: SheetMetalKFactor | C4: HemKFactor | D4: InsideBendRadiusMM | E4: MaterialThicknessMM | H4: MaterialGauges | I4: SheetMetalKFactor | J4: HemKFactor | K4: InsideBendRadiusMM | L4: MaterialThicknessMM
A5: 20 GA | B5: 0.089 | C5: 0.65 | D5: 1 | E5: 0.9 | H5: 20 GA | I5: 0.089 | J5: 0.65 | K5: 1 | L5: 0.9
A6: 18 GA | B6: 0.089 | C6: 0.65 | D6: 1 | E6: 1.22 | H6: 18 GA | I6: 0.089 | J6: 0.65 | K6: 1 | L6: 1.22
A7: 16 GA | B7: 0.124 | C7: 0.65 | D7: 1 | E7: 1.51 | H7: 16 GA | I7: 0.382 | J7: 0.65 | K7: 1 | L7: 1.51
A8: 14 GA | B8: 0.34 | C8: 0.65 | D8: 1 | E8: 1.91 | H8: 14 GA | I8: 0.34 | J8: 0.65 | K8: 1 | L8: 1.91
A9: 12 GA | B9: 0.34 | C9: 0.65 | D9: 1 | E9: 2.68 | H9: 12 GA | I9: 0.34 | J9: 0.65 | K9: 1 | L9: 2.68
A10: 10 GA | B10: 0.34 | C10: 0.65 | D10: 1 | E10: 3.175 | H10: 10 GA | I10: 0.34 | J10: 0.65 | K10: 1 | L10: 3.175
A11: 0.95mm | B11: 0.089 | C11: 0.65 | D11: 1 | E11: 0.95 | H11: 0.95mm | I11: 0.089 | J11: 0.65 | K11: 1 | L11: 0.95
A12: 1.00mm | B12: 0.182 | C12: 0.65 | D12: 0.5 | E12: 1 | H12: 1.00mm | I12: 0.182 | J12: 0.65 | K12: 0.5 | L12: 1
A13: 1.20mm | B13: 0.256 | C13: 0.65 | D13: 0.5 | E13: 1.2 | H13: 1.20mm | I13: 0.256 | J13: 0.65 | K13: 0.5 | L13: 1.2
A14: 1.25mm | B14: 0.256 | C14: 0.65 | D14: 0.5 | E14: 1.2 | H14: 1.25mm | I14: 0.256 | J14: 0.65 | K14: 0.5 | L14: 1.2
A15: 1.35mm | B15: 0.26 | C15: 0.65 | D15: 0.5 | E15: 1.35 | H15: 1.35mm | I15: 0.26 | J15: 0.65 | K15: 0.5 | L15: 1.35
A16: 1.50mm | B16: 0.206 | C16: 0.65 | D16: 0.5 | E16: 1.5 | H16: 1.50mm | I16: 0.206 | J16: 0.65 | K16: 0.5 | L16: 1.5
... A23: 12.0mm | B23: 0.209 | C23: 0.65 | D23: 0.5 | E23: 12 | H23: 12.0mm | I23: 0.209 | J23: 0.65 | K23: 0.5 | L23: 12

Sheet Set Material Name
A1: Set Material Name
A2: MaterialType | B2: StandardName | C2: OldName
A3: mm-S/S 4B/2B | B3: S/S 4B/2B | C3: S/S 4B/2B
A4: GA-S/S 4B/2B | B4: S/S - #4 | C4: S/S - #4
A5: mm-S/S Perf | B5: 4B/2B Perf10 | C5: 4B/2B Perf10
A6: GA-S/S Perf | B6: S/S PERF | C6: S/S PERF
A7: mm-S/S 2B/2B | B7: S/S 2B/2B | C7: S/S 2B/2B
A8: GA-S/S 2B/2B | B8: S/S - 2B | C8: S/S - 2B
A9: mm-Galv. Sheet | B9: GI | C9: GI
A10: GA-Galv. Sheet | B10: ALUM | C10: ALUM
A11: mm-Galv. Perf | B11: GI Perf10 | C11: GI Perf
A12: GA-Galv. Perf | B12: ALUM PERF | C12: ALUM PERF
A13: mm-Cold Rolled | B13: Q235 | C13: Q235
... A18: mm-FinL-Alum | B18: EN AW 5754 | C18: EN 1.4404 (X2CrNiMo17-12-2)

Sheet Change Material K Factors
A1: Change Material K Factors
A2: MaterialName | B2: InsidebendradiusmmM | C2: QtyBends | D2: SheetMetalKFactorM | E2: HemKFactormM | F2: MaterialThicknessmmM
A3: 20 GA S/S - #4 | B3: 1 | C3: 1 | D3: 0.089 | E3: 0.65 | F3: 0.9
A4: 18 GA S/S - #4 | B4: 1 | C4: 1 | D4: 0.089 | E4: 0.65 | F4: 1.22
A5: 16 GA S/S - #4 | B5: 1 | C5: 1 | D5: 0.124 | E5: 0.65 | F5: 1.51
A6: 14 GA S/S - #4 | B6: 1 | C6: 1 | D6: 0.34 | E6: 0.65 | F6: 1.91
A7: 12 GA S/S - #4 | B7: 1 | C7: 1 | D7: 0.36 | E7: 0.65 | F7: 2.68
A8: 20 GA C.R.S. | B8: 1 | C8: 1 | D8: 0.315 | E8: 0.65 | F8: 0.9
A9: 18 GA C.R.S. | B9: 1 | C9: 1 | D9: 0.3 | E9: 0.65 | F9: 1.22
A10: 16 GA C.R.S. | B10: 1 | C10: 1 | D10: 0.25 | E10: 0.65 | F10: 1.51
A11: 14 GA C.R.S. | B11: 1 | C11: 1 | D11: 0.34 | E11: 0.65 | F11: 1.91
A12: 12 GA C.R.S. | B12: 1 | C12: 1 | D12: 0.35 | E12: 0.65 | F12: 2.68
A13: 20 GA ALUM | B13: 1 | C13: 1 | D13: 0.315 | E13: 0.65 | F13: 0.9
A14: 18 GA ALUM | B14: 1 | C14: 1 | D14: 0.3 | E14: 0.65 | F14: 1.22
... A55: 10.0mm EN AW 5754 | B55: 1 | C55: 1 | D55: 0.25 | E55: 0.65 | F55: 10
